Traceback (most recent call last):
  File "/opt/hostedtoolcache/Python/3.9.16/x64/lib/python3.9/site-packages/jupyter_cache/executors/utils.py", line 58, in single_nb_execution
    executenb(
  File "/opt/hostedtoolcache/Python/3.9.16/x64/lib/python3.9/site-packages/nbclient/client.py", line 1204, in execute
    return NotebookClient(nb=nb, resources=resources, km=km, **kwargs).execute()
  File "/opt/hostedtoolcache/Python/3.9.16/x64/lib/python3.9/site-packages/nbclient/util.py", line 84, in wrapped
    return just_run(coro(*args, **kwargs))
  File "/opt/hostedtoolcache/Python/3.9.16/x64/lib/python3.9/site-packages/nbclient/util.py", line 62, in just_run
    return loop.run_until_complete(coro)
  File "/opt/hostedtoolcache/Python/3.9.16/x64/lib/python3.9/asyncio/base_events.py", line 647, in run_until_complete
    return future.result()
  File "/opt/hostedtoolcache/Python/3.9.16/x64/lib/python3.9/site-packages/nbclient/client.py", line 663, in async_execute
    await self.async_execute_cell(
  File "/opt/hostedtoolcache/Python/3.9.16/x64/lib/python3.9/site-packages/nbclient/client.py", line 965, in async_execute_cell
    await self._check_raise_for_error(cell, cell_index, exec_reply)
  File "/opt/hostedtoolcache/Python/3.9.16/x64/lib/python3.9/site-packages/nbclient/client.py", line 862, in _check_raise_for_error
    raise CellExecutionError.from_cell_and_msg(cell, exec_reply_content)
nbclient.exceptions.CellExecutionError: An error occurred while executing the following cell:
------------------
# boxplot 
box = alt.Chart(df).___().encode(
    x='___',
)

box
------------------

[0;31m---------------------------------------------------------------------------[0m
[0;31mAttributeError[0m                            Traceback (most recent call last)
Cell [0;32mIn[5], line 2[0m
[1;32m      1[0m [38;5;66;03m# boxplot [39;00m
[0;32m----> 2[0m box [38;5;241m=[39m [43malt[49m[38;5;241;43m.[39;49m[43mChart[49m[43m([49m[43mdf[49m[43m)[49m[38;5;241;43m.[39;49m[43m___[49m()[38;5;241m.[39mencode(
[1;32m      3[0m     x[38;5;241m=[39m[38;5;124m'[39m[38;5;124m___[39m[38;5;124m'[39m,
[1;32m      4[0m )
[1;32m      6[0m box

File [0;32m/opt/hostedtoolcache/Python/3.9.16/x64/lib/python3.9/site-packages/altair/utils/schemapi.py:278[0m, in [0;36mSchemaBase.__getattr__[0;34m(self, attr)[0m
[1;32m    276[0m [38;5;28;01mexcept[39;00m [38;5;167;01mAttributeError[39;00m:
[1;32m    277[0m     _getattr [38;5;241m=[39m [38;5;28msuper[39m(SchemaBase, [38;5;28mself[39m)[38;5;241m.[39m[38;5;21m__getattribute__[39m
[0;32m--> 278[0m [38;5;28;01mreturn[39;00m [43m_getattr[49m[43m([49m[43mattr[49m[43m)[49m

[0;31mAttributeError[0m: 'Chart' object has no attribute '___'
AttributeError: 'Chart' object has no attribute '___'

